Workbook

Sheet رئيسي
B1: حسابات الورشة - معمل
B2: الحساب | C2: ذهب | D2: دولار | F2: الحساب | G2: ذهب | H2: دولار
B3: ماكينات | D3: =ماكينات!H569 -> 306778 | F3: Paid from Ahmad | G3: =Ahmad!B767 -> -20000 | H3: =Ahmad!H569 -> -239039
B4: مصاريف تأسيس الورشة | D4: ='تأسيس ورشة'!H570 -> 163070.56 | F4: Paid from Mazen | G4: =Mzen!B769 -> 0 | H4: =Mzen!H571 -> -239792.56
B7: خزنة رئيسية | C7: ='خزنة رئيسية'!C18 -> 0 | D7: =دولار!H927 -> 39173 | F7: اجور مستلمة عن 21 | H7: ='مشغول 21'!H106 -> -1589
B8: تحت التصنيع | C8: ='تحت التصنيع'!B769 -> 11574.486 | D8: ='تحت التصنيع'!N571 -> 0 | F8: اجور مستلمة عن 18 | H8: ='مشغول 18'!H613 -> -160727
B9: مشغول 18 | C9: ='مشغول 18 (2)'!C1158 -> 4710.4078 | F9: profit | G9: =Pro!B767 -> -151.39 | H9: =Pro!H569 -> -213
B10: مشغول 21 | C10: ='مشغول 21 (2)'!C769 -> 105.59352
B11: كسر 18 | C11: ='كسر 18'!C770 -> 363.3104
B12: كسر21 | C12: ='كسر 21'!C770 -> 52.1076
B13: رملة | C13: =رملة!B1264 -> 458.65
B14: كسر 22 | C14: ='كسر 22 '!C769 -> 13.2132
B15: كسر صب 18 | C15: ='صب 18'!B1266 -> 588.9128
B17: SILVER $ | D17: =silver!H582 -> 14745
B18: شمع | D18: =شمع!H582 -> 0
B19: ALLOY سحب | D19: =ALLOY!H582 -> 381
B20: ALLOY صب | D20: ='ALLOY (2)'!H582 -> 0
B22: =زبائن!A1 -> زبائن ورشة | C22: =زبائن!B836 -> 1725.624 | D22: =زبائن!H638 -> 36559
B24: مصاريف تشغيلية | D24: ='مصاريف تشغيلية'!H582 -> 66978
B25: مصاريف شهرية | D25: ='مصاريف اخرى'!H795 -> 81510
B27: بورصة | D27: 10000
B28: متاجرة | C28: =Trading!B767 -> 559.08 | D28: =Trading!H569 -> -77834
B29: المجموع | C29: =SUM(C22,C28,C14,C13,C12,C11,C10,C8,C9,C15) -> 20151.385 | D29: =SUM(D3:D28) -> 641360.56 | F29: المجموع | G29: =SUM(G3:G28) -> -20151.39 | H29: =SUM(H3:H28) -> -641360.56
D32: =C29+G29 -> -0.0049206031 | F32: الفرق ذهب
D33: =D29+H29 -> 0 | F33: الفرق دولار
E135: تسليم ناتو للسحب
A136: 46212 | C136: 98.91 | E136: ف 002841 // مارك
K431: هاروت اوهانيان
K432: مانو
K433: كيفو
K434: كوكو
K435: عبد الستار
K436: رازميك
K437: مريم
K438: رافي
K439: ميهير

Sheet ماكينات
A1: قيمة ماكينات
A2: دهب 995 | D2: =A1 -> قيمة ماكينات | G2: حساب دولار $ | J2: =A1 -> قيمة ماكينات
A3: من تاريخ :
A4: إلى تاريخ : | G4: إلى تاريخ :
A5: التاريخ | B5: مدفوع له | C5: مستلم منه | D5: الرصيد | E5: البيان | G5: التاريخ | H5: لنا | I5: علينا | J5: الرصيد | K5: البيان
D6: =B6-C6 -> 0 | G6: 45931 | H6: 3500 | J6: =H6-I6 -> 3500 | K6: دفعة الى Gold Makina
D7: =D6+B7-C7 -> 0 | G7: 45932 | H7: 2000 | J7: =J6+H7-I7 -> 5500 | K7: دفعة الى عباس - من اصل 8.000$
D8: =D7+B8-C8 -> 0 | G8: 45947 | H8: 23400 | J8: =J7+H8-I8 -> 28900 | K8: مدفوع من احمد 20.000 يورو × 1.17 / ايطاليا
D9: =D8+B9-C9 -> 0 | G9: 45958 | H9: 17010 | J9: =J8+H9-I9 -> 45910 | K9: مدفوع من احمد تسكير حساب - كيومجي كينت Gold Makina
D10: =D9+B10-C10 -> 0 | G10: 46074 | H10: 8130 | J10: =J9+H10-I10 -> 54040 | K10: قوالب ستيل اقلام و مكنات و ايماي
D11: =D10+B11-C11 -> 0 | G11: 46074 | H11: 12000 | J11: =J10+H11-I11 -> 66040 | K11: مكنات نزار دمغة
D12: =D11+B12-C12 -> 0 | G12: 46074 | H12: 6520 | J12: =J11+H12-I12 -> 72560 | K12: مكينات سحب
D13: =D12+B13-C13 -> 0 | G13: 46074 | H13: 8500 | J13: =J12+H13-I13 -> 81060 | K13: مكنات نقش و زخرفة
D14: =D13+B14-C14 -> 0 | G14: 46134 | H14: 6870 | J14: =J13+H14-I14 -> 87930 | K14: مكينات
D15: =D14+B15-C15 -> 0 | G15: 46134 | H15: 3000 | J15: =J14+H15-I15 -> 90930 | K15: مكينات
D16: =D15+B16-C16 -> 0 | G16: 46134 | H16: 53100 | J16: =J15+H16-I16 -> 144030 | K16: مكينات
D17: =D16+B17-C17 -> 0 | H17: 10000 | J17: =J16+H17-I17 -> 154030 | K17: مكينات
D18: =D17+B18-C18 -> 0 | G18: 46148 | H18: 4500 | J18: =J17+H18-I18 -> 158530 | K18: مدفوع من صندوق علي ) دفعة من ماكينات النقش
D19: =D18+B19-C19 -> 0 | G19: 46150 | H19: 10072 | J19: =J18+H19-I19 -> 168602 | K19: مكنات
D20: =D19+B20-C20 -> 0 | G20: 46150 | I20: =3200+4200 -> 7400 | J20: =J19+H20-I20 -> 161202 | K20: اعادة لحساب احمد
D21: =D20+B21-C21 -> 0 | G21: 46150 | H21: 74736 | J21: =J20+H21-I21 -> 235938 | K21: مازن ماكينات
D22: =D21+B22-C22 -> 0 | G22: 46252 | H22: 59020 | J22: =J21+H22-I22 -> 294958 | K22: مكنات ايطاليا
D23: =D22+B23-C23 -> 0 | G23: 46273 | H23: 5000 | J23: =J22+H23-I23 -> 299958 | K23: ثمن موتير 11300
D24: =D23+B24-C24 -> 0 | G24: 46287 | H24: 6820 | J24: =J23+H24-I24 -> 306778 | K24: ثمن المولد نقل على المكينات
D25: =D24+B25-C25 -> 0 | J25: =J24+H25-I25 -> 306778
D26: =D25+B26-C26 -> 0 | J26: =J25+H26-I26 -> 306778
D27: =D26+B27-C27 -> 0 | J27: =J26+H27-I27 -> 306778
D28: =D27+B28-C28 -> 0 | J28: =J27+H28-I28 -> 306778
D29: =D28+B29-C29 -> 0 | J29: =J28+H29-I29 -> 306778
D30: =D29+B30-C30 -> 0 | J30: =J29+H30-I30 -> 306778
D31: =D30+B31-C31 -> 0 | J31: =J30+H31-I31 -> 306778
D32: =D31+B32-C32 -> 0 | J32: =J31+H32-I32 -> 306778
D33: =D32+B33-C33 -> 0 | J33: =J32+H33-I33 -> 306778
D34: =D33+B34-C34 -> 0 | J34: =J33+H34-I34 -> 306778
D35: =D34+B35-C35 -> 0 | J35: =J34+H35-I35 -> 306778
D36: =D35+B36-C36 -> 0 | J36: =J35+H36-I36 -> 306778
... D567: =D566+B567-C567 -> 0 | J567: =J566+H567-I567 -> 306778
D568: =D567+B568-C568 -> 0 | G568: المجموع | H568: =SUM(H6:H567) -> 314178 | I568: =SUM(I6:I567) -> 7400 | J568: =H568-I568 -> 306778
D569: =D568+B569-C569 -> 0 | G569: الرصيد | H569: =H568-I568 -> 306778 | I569: لنا معكم دولار
D570: =D569+B570-C570 -> 0
...

Sheet مصاريف اخرى
A1: مصاريف اخرى
A2: دهب 995 | D2: =A1 -> مصاريف اخرى | G2: حساب دولار $ | J2: =A1 -> مصاريف اخرى
A3: من تاريخ :
A4: إلى تاريخ : | G4: إلى تاريخ :
A5: التاريخ | B5: مدفوع له | C5: مستلم منه | D5: الرصيد | E5: البيان | G5: التاريخ | H5: مدفوع | I5: مرتجع مصروف | J5: رصيد المصروف | K5: البيان
D6: =B6-C6 -> 0 | G6: . | H6: 12000 | J6: =H6-I6 -> 12000 | K6: مدفوع من مازن اجار الورشة 1/9 لغاية 1/9/26
D7: =D6+B7-C7 -> 0 | G7: 46164 | H7: 700 | J7: =J6+H7-I7 -> 12700 | K7: ناتو / فتوح / جهاد
D8: =D7+B8-C8 -> 0 | G8: 46168 | H8: 30 | J8: =J7+H8-I8 -> 12730 | K8: مخرطة بيد جهاد
D9: =D8+B9-C9 -> 0 | G9: 46168 | H9: 250 | J9: =J8+H9-I9 -> 12980 | K9: جهاد معاش
D10: =D9+B10-C10 -> 0 | G10: 46168 | H10: 120 | J10: =J9+H10-I10 -> 13100 | K10: مصروف فاتورة سيتي ستار
D11: =D10+B11-C11 -> 0 | G11: 46174 | H11: 3650 | J11: =J10+H11-I11 -> 16750 | K11: معاشات
D12: =#REF!+B12-C12 -> #REF! | G12: 46174 | H12: 124 | J12: =J11+H12-I12 -> 16874 | K12: مازن غراض قاروط
D13: =D12+B13-C13 -> #REF! | G13: 46174 | H13: 100 | J13: =J12+H13-I13 -> 16974 | K13: علي غراض قاروط
D14: =D13+B14-C14 -> #REF! | G14: 46174 | H14: 12 | J14: =J13+H14-I14 -> 16986 | K14: فاتورة habtraco brass 6mm
D15: =D14+B15-C15 -> #REF! | G15: 46175 | H15: 10 | J15: =J14+H15-I15 -> 16996 | K15: مياه
D16: =D15+B16-C16 -> #REF! | G16: 46176 | H16: 200 | J16: =J15+H16-I16 -> 17196 | K16: تكملة معاش ناتو
D17: =D16+B17-C17 -> #REF! | G17: 46177 | H17: 165 | J17: =J16+H17-I17 -> 17361 | K17: شراء حجار صمباط
D18: =D17+B18-C18 -> #REF! | G18: 46181 | H18: 120 | J18: =J17+H18-I18 -> 17481 | K18: فتوح
D19: =D18+B19-C19 -> #REF! | G19: 46181 | H19: 50 | J19: =J18+H19-I19 -> 17531 | K19: شراء حجار صمباط
D20: =D19+B20-C20 -> #REF! | G20: 46182 | H20: 400 | J20: =J19+H20-I20 -> 17931 | K20: هوفيغ
D21: =D20+B21-C21 -> #REF! | G21: 46182 | H21: 1225 | J21: =J20+H21-I21 -> 19156 | K21: سفرة مازن و علي
D22: =D21+B22-C22 -> #REF! | G22: 46183 | H22: 67 | J22: =J21+H22-I22 -> 19223 | K22: هاروط
D23: =D22+B23-C23 -> #REF! | G23: 46183 | H23: 20 | J23: =J22+H23-I23 -> 19243 | K23: رصور 2.14
D24: =D23+B24-C24 -> #REF! | G24: 46184 | H24: 200 | J24: =J23+H24-I24 -> 19443 | K24: ناتو سحب عالمعاش
D25: =#REF!+B25-C25 -> #REF! | G25: 46184 | H25: 165 | J25: =J24+H25-I25 -> 19608 | K25: هاروط
D26: =D25+B26-C26 -> #REF! | G26: 46184 | H26: 40 | J26: =J25+H26-I26 -> 19648 | K26: هاروط
D27: =D26+B27-C27 -> #REF! | G27: 46184 | H27: 100 | J27: =J26+H27-I27 -> 19748 | K27: فتوح سحب عالمعاش
D28: =D27+B28-C28 -> #REF! | G28: 46185 | H28: 130 | J28: =J27+H28-I28 -> 19878 | K28: سلفة vicken
D29: =D28+B29-C29 -> #REF! | G29: 46185 | H29: 200 | J29: =J28+H29-I29 -> 20078 | K29: سلفة هاروط
D30: =D29+B30-C30 -> #REF! | G30: 46189 | H30: 6 | J30: =J29+H30-I30 -> 20084 | K30: مياه
G31: 46189 | H31: 160 | J31: =J30+H31-I31 -> 20244 | K31: غراض بيد مازن
D32: =D30+B32-C32 -> #REF! | G32: 46189 | H32: 70 | J32: =J31+H32-I32 -> 20314 | K32: احمد اغا
D33: =D32+B33-C33 -> #REF! | G33: 46189 | H33: 250 | J33: =J32+H33-I33 -> 20564 | K33: سلفة vicken
D34: =D33+B34-C34 -> #REF! | G34: 46189 | H34: 100 | J34: =J33+H34-I34 -> 20664 | K34: سلفة فتوح
D35: =D34+B35-C35 -> #REF! | G35: 46190 | H35: 200 | J35: =J34+H35-I35 -> 20864 | K35: بيد هاروط
D36: =D35+B36-C36 -> #REF! | G36: 46190 | H36: 200 | J36: =J35+H36-I36 -> 21064 | K36: سلفة هاروط
D37: =D36+B37-C37 -> #REF! | G37: 46195 | H37: 1571 | J37: =J36+H37-I37 -> 22635 | K37: بلدية
D38: =D37+B38-C38 -> #REF! | G38: 46195 | H38: 65 | J38: =J37+H38-I38 -> 22700 | K38: ارغون
D39: =D38+B39-C39 -> #REF! | G39: 46196 | H39: 16 | J39: =J38+H39-I39 -> 22716 | K39: غراض بيد مازن
G40: 46196 | H40: 150 | J40: =J39+H40-I40 -> 22866 | K40: ف 948
...

Sheet مصاريف تشغيلية
A1: مصاريف تشغيلية
A2: دهب 995 | D2: =A1 -> مصاريف تشغيلية | G2: حساب دولار $ | J2: =A1 -> مصاريف تشغيلية
A3: من تاريخ :
A4: إلى تاريخ : | G4: إلى تاريخ :
A5: التاريخ | B5: مدفوع له | C5: مستلم منه | D5: الرصيد | E5: البيان | G5: التاريخ | H5: مدفوع | I5: مرتجع مصروف | J5: رصيد المصروف | K5: البيان
D6: =B6-C6 -> 0 | J6: =H6-I6 -> 0
D7: =D6+B7-C7 -> 0 | H7: 24000 | J7: =J6+H7-I7 -> 24000 | K7: شمع
D8: =D7+B8-C8 -> 0 | H8: 27000 | J8: =J7+H8-I8 -> 51000 | K8: شمع
D9: =D8+B9-C9 -> 0 | H9: 3000 | J9: =J8+H9-I9 -> 54000 | K9: شمع
D10: =D9+B10-C10 -> 0 | G10: 46164 | H10: 2310 | J10: =J9+H10-I10 -> 56310 | K10: من تاريخ 8/5/2026 لغاية 22/5/2026 على الغروب
D11: =D10+B11-C11 -> 0 | G11: 46167 | H11: 49.5 | J11: =J10+H11-I11 -> 56359.5 | K11: شراء عدة هاروت ف // 768
D12: =D11+B12-C12 -> 0 | G12: 46167 | H12: 5.5 | J12: =J11+H12-I12 -> 56365 | K12: شراء عدة هاروت ف // مكتبة حسون
D13: =D12+B13-C13 -> 0 | G13: 46167 | H13: 10 | J13: =J12+H13-I13 -> 56375 | K13: شمع من الرضوان
D14: =D13+B14-C14 -> 0 | G14: 46167 | H14: 300 | J14: =J13+H14-I14 -> 56675 | K14: شراء اللوي سحب
G15: 46174 | H15: 12 | J15: =J14+H15-I15 -> 56687 | K15: قوالب سليكون
G16: 46174 | H16: 385 | J16: =J15+H16-I16 -> 57072 | K16: سلندر جفصين
D17: =D14+B17-C17 -> 0 | G17: 46175 | H17: 2600 | J17: =J16+H17-I17 -> 59672 | K17: مدفوع قولب غورميت
D18: =D17+B18-C18 -> 0 | G18: 46175 | H18: 625 | J18: =J17+H18-I18 -> 60297 | K18: مجموع فواتير مشتريات هاروط
D19: =D18+B19-C19 -> 0 | G19: 46176 | H19: 181 | J19: =J18+H19-I19 -> 60478 | K19: مجموع فواتير مشتريات هاروط
D20: =D19+B20-C20 -> 0 | G20: 46177 | H20: 115 | J20: =J19+H20-I20 -> 60593 | K20: قوالب سليكون
D21: =D20+B21-C21 -> 0 | G21: 46178 | H21: 150 | J21: =J20+H21-I21 -> 60743 | K21: شراء زيكزيك
D22: =D21+B22-C22 -> 0 | G22: 46178 | H22: 73 | J22: =J21+H22-I22 -> 60816 | K22: شراء فريزات
D23: =D22+B23-C23 -> 0 | G23: 46178 | H23: 17 | J23: =J22+H23-I23 -> 60833 | K23: شراء زيركون
D24: =D23+B24-C24 -> 0 | G24: 46182 | H24: 5430 | J24: =J23+H24-I24 -> 66263 | K24: مدفوع مسجل على حساب مازن
G25: 46184 | H25: 70 | J25: =J24+H25-I25 -> 66333 | K25: بلكسي للميزان
D26: =D24+B26-C26 -> 0 | G26: 46185 | H26: 2100 | J26: =J25+H26-I26 -> 68433 | K26: احمد اغا
D27: =D26+B27-C27 -> 0 | G27: 46189 | H27: 280 | J27: =J26+H27-I27 -> 68713 | K27: شحن مكنة النقش
G28: 46196 | H28: 140 | J28: =J27+H28-I28 -> 68853 | K28: هاروت غراض
D29: =D27+B29-C29 -> 0 | G29: 46206 | H29: 4700 | J29: =J28+H29-I29 -> 73553 | K29: ميزان عدد 2 بوغوصيان
D30: =D29+B30-C30 -> 0 | G30: 46206 | H30: 500 | J30: =J29+H30-I30 -> 74053 | K30: نجار
G31: 46209 | H31: 779 | J31: =J30+H31-I31 -> 74832 | K31: هاروت غراض
D32: =D30+B32-C32 -> 0 | G32: 46211 | H32: 60 | J32: =J31+H32-I32 -> 74892 | K32: قوالب سليكون
G33: 46213 | H33: 20 | J33: =J32+H33-I33 -> 74912 | K33: زيركون
D34: =D32+B34-C34 -> 0 | G34: 46218 | H34: 237 | J34: =J33+H34-I34 -> 75149 | K34: غراض
G35: 46219 | H35: 1250 | J35: =J34+H35-I35 -> 76399 | K35: شمع مصطفى
D36: =D34+B36-C36 -> 0 | G36: 46219 | H36: 30 | J36: =J35+H36-I36 -> 76429 | K36: حبال
D37: =D36+B37-C37 -> 0 | G37: 46220 | H37: 38 | J37: =J36+H37-I37 -> 76467 | K37: بوغوصيان
G38: 46224 | H38: 14 | J38: =J37+H38-I38 -> 76481 | K38: قوالب سليكون
G39: 46226 | H39: 20 | J39: =J38+H39-I39 -> 76501 | K39: فليارات
D40: =D37+B40-C40 -> 0 | G40: 46234 | H40: 355 | J40: =J39+H40-I40 -> 76856 | K40: ميكروسكوب
...

Sheet Cash
A1: خزنة - Cash
A2: دهب 995 | D2: =A1 -> خزنة - Cash | G2: حساب دولار $ | J2: =A1 -> خزنة - Cash
A3: من تاريخ :
A4: إلى تاريخ : | G4: إلى تاريخ :
A5: التاريخ | B5: مدفوع له | C5: مستلم منه | D5: الرصيد | E5: البيان | G5: التاريخ | H5: لنا | I5: علينا | J5: الرصيد | K5: البيان
D6: =B6-C6 -> 0 | G6: 45931 | H6: 10000 | J6: =H6-I6 -> 10000 | K6: مستلم من احمد دفعة في استانبول
D7: =D6+B7-C7 -> 0 | G7: 45932 | I7: 3500 | J7: =J6+H7-I7 -> 6500 | K7: دفعة الى Gold Makina
D8: =D7+B8-C8 -> 0 | G8: 45932 | I8: 2000 | J8: =J7+H8-I8 -> 4500 | K8: دفعة الى عباس - من اصل 8.000$
D9: =D8+B9-C9 -> 0 | I9: 4500 | J9: =J8+H9-I9 -> 0 | K9: مستلم دفعة لماكينات النقش
D10: =D9+B10-C10 -> 0 | J10: =J9+H10-I10 -> 0
D11: =D10+B11-C11 -> 0 | J11: =J10+H11-I11 -> 0
D12: =D11+B12-C12 -> 0 | J12: =J11+H12-I12 -> 0
D13: =D12+B13-C13 -> 0 | J13: =J12+H13-I13 -> 0
D14: =D13+B14-C14 -> 0 | J14: =J13+H14-I14 -> 0
D15: =D14+B15-C15 -> 0 | J15: =J14+H15-I15 -> 0
D16: =D15+B16-C16 -> 0 | J16: =J15+H16-I16 -> 0
D17: =D16+B17-C17 -> 0 | J17: =J16+H17-I17 -> 0
D18: =D17+B18-C18 -> 0 | J18: =J17+H18-I18 -> 0
D19: =D18+B19-C19 -> 0 | J19: =J18+H19-I19 -> 0
D20: =D19+B20-C20 -> 0 | J20: =J19+H20-I20 -> 0
D21: =D20+B21-C21 -> 0 | J21: =J20+H21-I21 -> 0
... D567: =D566+B567-C567 -> 0 | J567: =J566+H567-I567 -> 0
D568: =D567+B568-C568 -> 0 | G568: المجموع | H568: =SUM(H6:H567) -> 10000 | I568: =SUM(I6:I567) -> 10000 | J568: =H568-I568 -> 0
D569: =D568+B569-C569 -> 0 | G569: الرصيد | H569: =H568-I568 -> 0
D570: =D569+B570-C570 -> 0
D571: =D570+B571-C571 -> 0
D572: =D571+B572-C572 -> 0
D573: =D572+B573-C573 -> 0
D574: =D573+B574-C574 -> 0
D575: =D574+B575-C575 -> 0
D576: =D575+B576-C576 -> 0
D577: =D576+B577-C577 -> 0
D578: =D577+B578-C578 -> 0
D579: =D578+B579-C579 -> 0
D580: =D579+B580-C580 -> 0
D581: =D580+B581-C581 -> 0
... D765: =D764+B765-C765 -> 0
A766: المجموع | B766: =SUM(B6:B765) -> 0 | C766: =SUM(C6:C765) -> 0 | D766: =B766-C766 -> 0
A767: الرصيد | B767: =B766-C766 -> 0
J768: =H569 -> 0 | K768: الرصيد

Sheet تأسيس ورشة
A1: مصروف تأسيس ورشة
A2: دهب 995 | D2: =A1 -> مصروف تأسيس ورشة | G2: حساب دولار $ | J2: =A1 -> مصروف تأسيس ورشة
A3: من تاريخ :
A4: إلى تاريخ : | G4: إلى تاريخ :
A5: التاريخ | B5: مدفوع له | C5: مستلم منه | D5: الرصيد | E5: البيان | G5: التاريخ | H5: مدفوع | I5: مرتجع مصروف | J5: رصيد المصروف | K5: البيان
D6: =B6-C6 -> 0 | G6: 45905 | H6: 1000 | J6: =H6-I6 -> 1000 | K6: دفعة بيد احمد اغا
D7: =D6+B7-C7 -> 0 | G7: 45911 | H7: 3000 | J7: =J6+H7-I7 -> 4000 | K7: دفعة بيد احمد اغا
D8: =D7+B8-C8 -> 0 | G8: 45919 | H8: 3000 | J8: =J7+H8-I8 -> 7000 | K8: دفعة بيد احمد اغا
D9: =D8+B9-C9 -> 0 | G9: 45938 | H9: 3000 | J9: =J8+H9-I9 -> 10000 | K9: دفعة بيد احمد اغا
D10: =D9+B10-C10 -> 0 | G10: 45940 | H10: 3000 | J10: =J9+H10-I10 -> 13000 | K10: دفعة بيد فارتان - الحداد
D11: =D10+B11-C11 -> 0 | G11: 45943 | H11: 465 | J11: =J10+H11-I11 -> 13465 | K11: دفعة بيد قاسم - زجاج
D12: =D11+B12-C12 -> 0 | G12: 45946 | H12: 1500 | J12: =J11+H12-I12 -> 14965 | K12: دفعة بيد محمد علوية من اصل 2750$
D13: =D12+B13-C13 -> 0 | G13: 45951 | H13: 3000 | J13: =J12+H13-I13 -> 17965 | K13: دفعة بيد احمد اغا
D14: =D13+B14-C14 -> 0 | G14: 45961 | H14: 3000 | J14: =J13+H14-I14 -> 20965 | K14: دفعة بيد احمد اغا
D15: =D14+B15-C15 -> 0 | J15: =J14+H15-I15 -> 20965
D16: =D15+B16-C16 -> 0 | H16: 1250 | J16: =J15+H16-I16 -> 22215 | K16: المنيوم
D17: =D16+B17-C17 -> 0 | H17: 850 | J17: =J16+H17-I17 -> 23065 | K17: بلانكو 1 طن
D18: =D17+B18-C18 -> 0 | H18: 477 | J18: =J17+H18-I18 -> 23542 | K18: axial fan
D19: =D18+B19-C19 -> 0 | H19: 300 | J19: =J18+H19-I19 -> 23842 | K19: خزنة من اصل 800
D20: =D19+B20-C20 -> 0 | H20: 5300 | J20: =J19+H20-I20 -> 29142 | K20: 10 مكيفات
D21: =D20+B21-C21 -> 0 | H21: 800 | J21: =J20+H21-I21 -> 29942 | K21: خزنةتسكير حساب
D22: =D21+B22-C22 -> 0 | H22: 1100 | J22: =J21+H22-I22 -> 31042 | K22: طاولات عدد 7
D23: =D22+B23-C23 -> 0 | H23: 410 | J23: =J22+H23-I23 -> 31452 | K23: ونش لنقل الخزنة
D24: =D23+B24-C24 -> 0 | J24: =J23+H24-I24 -> 31452
D25: =D24+B25-C25 -> 0 | H25: 300 | J25: =J24+H25-I25 -> 31752 | K25: جهاد ياسو
D26: =D25+B26-C26 -> 0 | H26: 1000 | J26: =J25+H26-I26 -> 32752 | K26: نجار مصطفى
D27: =D26+B27-C27 -> 0 | H27: 32.56 | J27: =J26+H27-I27 -> 32784.56 | K27: مفتا ح شق 2361 فاتورة
D28: =D27+B28-C28 -> 0 | H28: 280 | J28: =J27+H28-I28 -> 33064.56 | K28: ثمن عدة
D29: =D28+B29-C29 -> 0 | H29: 100 | J29: =J28+H29-I29 -> 33164.56 | K29: ونش لنق لمكنة
D30: =D29+B30-C30 -> 0 | H30: 109 | J30: =J29+H30-I30 -> 33273.56 | K30: عدة +غاز
D31: =D30+B31-C31 -> 0 | H31: 2100 | J31: =J30+H31-I31 -> 35373.56 | K31: خارتان الحداد
D32: =D31+B32-C32 -> 0 | H32: 60 | J32: =J31+H32-I32 -> 35433.56 | K32: مقص وزرديات و قضيب لحام
D33: =D32+B33-C33 -> 0 | H33: 230 | J33: =J32+H33-I33 -> 35663.56 | K33: نقل مكينات
D34: =D33+B34-C34 -> 0 | H34: 70 | J34: =J33+H34-I34 -> 35733.56 | K34: فليارات لمكنات السحب
D35: =D34+B35-C35 -> 0 | H35: 2310 | J35: =J34+H35-I35 -> 38043.56 | K35: جهاد ياسو
D36: =D35+B36-C36 -> 0 | H36: 800 | J36: =J35+H36-I36 -> 38843.56 | K36: كاتب عدل تاسيس شركة اورا غولد
... D49: =D48+B49-C49 -> 0 | H49: 20 | J49: =J48+H49-I49 -> 58128.56 | K49: صحون للشمع
D50: =D49+B50-C50 -> 0 | H50: =39513-2726+54-210+1 -> 36632 | J50: =J49+H50-I50 -> 94760.56 | K50: مصاريف متنوعة من مازن لغاية اول انتاج
D51: =D50+B51-C51 -> 0 | H51: 54000 | J51: =J50+H51-I51 -> 148760.56
D52: =D51+B52-C52 -> 0 | H52: 12000 | J52: =J51+H52-I52 -> 160760.56
...

Sheet Pro
A1: Pro
A2: دهب 995 | D2: =A1 -> Pro | G2: حساب دولار $ | J2: =A1 -> Pro
A3: من تاريخ :
A4: إلى تاريخ : | G4: إلى تاريخ :
A5: التاريخ | B5: خسارة | C5: ربح | D5: الرصيد | E5: البيان | G5: التاريخ | H5: مدفوع | I5: مستلم | J5: الرصيد | K5: البيان
A6: 46161 | C6: 0.39 | D6: =B6-C6 -> -0.39 | E6: تسليم محمد محابس 18 // 193.64 غ | I6: 3 | J6: =H6-I6 -> -3
A7: 46164 | C7: 0.08 | D7: =D6+B7-C7 -> -0.47 | E7: تسليم الزاوية مشغول 18 // 32.34 غ | G7: 46185 | I7: 215 | J7: =J6+H7-I7 -> -218 | K7: ربح مبيع مشغول 18
A8: 46167 | B8: 0.22 | C8: 0.13 | D8: =D7+B8-C8 -> -0.38 | E8: تسليم وسيم تميمي مشغول 18 // 70.51 غ | H8: 5 | J8: =J7+H8-I8 -> -213 | K8: ف 4453
A9: 46168 | C9: 0.08 | D9: =D8+B9-C9 -> -0.46 | E9: تسليم احمد كنجو مشغول 18 | J9: =J8+H9-I9 -> -213
A10: 46168 | C10: 0.08 | D10: =D9+B10-C10 -> -0.54 | E10: تسليم محمد عيساوي مشغول 18 | J10: =J9+H10-I10 -> -213
A11: 46168 | C11: 1.89 | D11: =D10+B11-C11 -> -2.43 | E11: فرق صب شجر 2362.32 // 18 // | J11: =J10+H11-I11 -> -213
A12: 46176 | B12: 0.16 | D12: =D11+B12-C12 -> -2.27 | E12: فرق كادر ليرة من مازن | J12: =J11+H12-I12 -> -213
A13: 46177 | C13: 0.83 | D13: =D12+B13-C13 -> -3.1 | E13: فرق صب سبيكة 915.81 | J13: =J12+H13-I13 -> -213
A14: 46177 | C14: 0.23 | D14: =D13+B14-C14 -> -3.33 | E14: فاتورة 002803 محمد سعيفان | J14: =J13+H14-I14 -> -213
A15: 46177 | C15: 0.06 | D15: =D14+B15-C15 -> -3.39 | E15: فاتورة 002804 محمد سعيفان | J15: =J14+H15-I15 -> -213
A16: 46177 | C16: 0.24 | D16: =D15+B16-C16 -> -3.63 | E16: فاتورة 002805 محمد عمار | J16: =J15+H16-I16 -> -213
A17: 46178 | B17: 11.46 | D17: =D16+B17-C17 -> 7.83 | E17: فرق المشغول 750 / 748 | J17: =J16+H17-I17 -> -213
A18: 46181 | C18: 0.08 | D18: =D17+B18-C18 -> 7.75 | E18: تسليم مازن بلاك // 38.53 // 18 | J18: =J17+H18-I18 -> -213
A19: 46182 | B19: 0.26 | D19: =D18+B19-C19 -> 8.01 | E19: فرق مستلم محابس من عيسى | J19: =J18+H19-I19 -> -213
A20: 46182 | B20: 0.16 | D20: =D19+B20-C20 -> 8.17 | E20: فرق مستلم سنسال فورسا | J20: =J19+H20-I20 -> -213
A21: 46182 | B21: 0.06 | D21: =D20+B21-C21 -> 8.23 | E21: فرق مستلم سنسال فورسا | J21: =J20+H21-I21 -> -213
A22: 46183 | C22: 0.05 | D22: =D21+B22-C22 -> 8.18 | J22: =J21+H22-I22 -> -213
A23: 46184 | B23: 0.07 | C23: 0.23 | D23: =D22+B23-C23 -> 8.02 | E23: ف 002812 // ريم كجوج | J23: =J22+H23-I23 -> -213
A24: 46184 | C24: 0.02 | D24: =D23+B24-C24 -> 8 | E24: ف 002812 // ريم كجوج | J24: =J23+H24-I24 -> -213
A25: 46206 | C25: 0.26 | D25: =D24+B25-C25 -> 7.74 | E25: ف 002808 // عيساوي | J25: =J24+H25-I25 -> -213
A26: 46185 | C26: 0.17 | D26: =D25+B26-C26 -> 7.57 | E26: ف 002810 // محمد عمار | J26: =J25+H26-I26 -> -213
A27: 46185 | C27: 0.07 | D27: =D26+B27-C27 -> 7.5 | E27: ف 002813 // جرادي | J27: =J26+H27-I27 -> -213
A28: 46185 | C28: 0.1 | D28: =D27+B28-C28 -> 7.4 | E28: مبيع مشغول 18 | J28: =J27+H28-I28 -> -213
A29: 46188 | B29: 0.13 | D29: =D28+B29-C29 -> 7.53 | E29: فرق القفل 750 | J29: =J28+H29-I29 -> -213
A30: 46189 | C30: 0.22 | D30: =D29+B30-C30 -> 7.31 | E30: ف 002815 // اسيل | J30: =J29+H30-I30 -> -213
A31: 46190 | C31: 0.64 | D31: =D30+B31-C31 -> 6.67 | E31: ف 002816 // عطولي | J31: =J30+H31-I31 -> -213
A32: 46196 | C32: 0.17 | D32: =D31+B32-C32 -> 6.5 | E32: ف 002821 // جرادي | J32: =J31+H32-I32 -> -213
A33: 46197 | C33: 0.05 | D33: =D32+B33-C33 -> 6.45 | E33: ف 002820 // محمد عمار | J33: =J32+H33-I33 -> -213
A34: 46198 | C34: 0.3 | D34: =D33+B34-C34 -> 6.15 | E34: علي زهور | J34: =J33+H34-I34 -> -213
A35: 46198 | B35: 0.15 | D35: =D34+B35-C35 -> 6.3 | E35: فورسا | J35: =J34+H35-I35 -> -213
A36: 46202 | B36: 0.77 | D36: =D35+B36-C36 -> 7.07 | E36: خياس اسوارة تركيب | J36: =J35+H36-I36 -> -213
A37: 46203 | C37: 0.02 | D37: =D36+B37-C37 -> 7.05 | E37: اسوارة تركيب | J37: =J36+H37-I37 -> -213
A38: 46204 | C38: 0.24 | D38: =D37+B38-C38 -> 6.81 | E38: ف 002824 // محمد سعيفان | J38: =J37+H38-I38 -> -213
A39: 46206 | C39: 0.43 | D39: =D38+B39-C39 -> 6.38 | E39: ف 002814 // جرادي محل | J39: =J38+H39-I39 -> -213
A40: 46206 | C40: 3.15 | D40: =D39+B40-C40 -> 3.23 | E40: ف 002822 // سليم عطالله | J40: =J39+H40-I40 -> -213
...

Sheet Ahmad
A1: Paid from AHMAD
A2: دهب 995 | D2: =A1 -> Paid from AHMAD | G2: حساب دولار $ | J2: =A1 -> Paid from AHMAD
A3: من تاريخ :
A4: إلى تاريخ : | G4: إلى تاريخ :
A5: التاريخ | B5: مدفوع له | C5: مستلم منه | D5: الرصيد | E5: البيان | G5: التاريخ | H5: Debit | I5: Credit | J5: الرصيد | K5: البيان
A6: 46157 | C6: =1256.48/2 -> 628.24 | D6: =B6-C6 -> -628.24 | E6: تسليم مازن رملة من اورا | G6: 45947 | I6: 10000 | J6: =H6-I6 -> -10000 | K6: مدفوع من احمد 10.000$ استانبول - صندوق
A7: 46157 | C7: 628.24 | D7: =D6+B7-C7 -> -1256.48 | E7: تسليم مازن رملة من اورا | G7: 45947 | I7: 23400 | J7: =J6+H7-I7 -> -33400 | K7: مدفوع من احمد 20.000 يورو × 1.17
A8: 46157 | C8: 74.31 | D8: =D7+B8-C8 -> -1330.79 | E8: تسليم مازن رملة من تايغر | G8: 45958 | I8: =17010-4200 -> 12810 | J8: =J7+H8-I8 -> -46210 | K8: مدفوع من احمد - كيومجي كينت
A9: 46157 | C9: 2536.95 | D9: =D8+B9-C9 -> -3867.74 | E9: تسليم مازن رملة من تايغر | G9: 45979 | I9: 6870 | J9: =J8+H9-I9 -> -53080 | K9: كيوجي كنت ماكينات
A10: 46157 | C10: 145.95 | D10: =D9+B10-C10 -> -4013.69 | E10: تسليم مازن رملة من تايغر | G10: 46035 | I10: 3000 | J10: =J9+H10-I10 -> -56080 | K10: قيمة شمعات
A11: 46157 | C11: 986.31 | D11: =D10+B11-C11 -> -5000 | E11: تسليم مازن رملة من تايغر | G11: 46035 | I11: 27000 | J11: =J10+H11-I11 -> -83080 | K11: قيمة شمعات | M11: =21886-11814 -> 10072
D12: =D11+B12-C12 -> -5000 | E12: استلام من المساهمين 8 كيلو من ارباح تايغر | G12: 46042 | I12: 3000 | J12: =J11+H12-I12 -> -86080 | K12: بيد علي
A13: 46178 | C13: 600 | D13: =D12+B13-C13 -> -5600 | E13: استلام رملي من تايغر | G13: 46057 | I13: 53100 | J13: =J12+H13-I13 -> -139180 | K13: مكنات ايطاليا
A14: 46178 | C14: 4012.87 | D14: =D13+B14-C14 -> -9612.87 | E14: مستلم مشغول 18 // 5323.75 // | G14: 46062 | I14: 24000 | J14: =J13+H14-I14 -> -163180 | K14: قيمة شمعات
A15: 46178 | C15: 342.48 | D15: =D14+B15-C15 -> -9955.35 | E15: مستلم مشغول 21 // 389.45 // | G15: 46083 | I15: =10000-3200 -> 6800 | J15: =J14+H15-I15 -> -169980 | K15: مكنات تركيا
A16: 46178 | C16: 301.6 | D16: =D15+B16-C16 -> -10256.95 | E16: مستلم كسر 18 // 407.58 // | G16: 46150 | I16: 10072 | J16: =J15+H16-I16 -> -180052 | K16: مكنات
A17: 46178 | C17: 89.76 | D17: =D16+B17-C17 -> -10346.71 | E17: مستلم كسر 21 // 103.78 // | I17: 18297 | J17: =J16+H17-I17 -> -198349 | K17: مستلم من المساهمين تسوية لحساب مازن
A18: 46181 | C18: 4653.29 | D18: =D17+B18-C18 -> -15000 | E18: استلام رملي من تايغر | G18: 46164 | I18: 1180 | J18: =J17+H18-I18 -> -199529 | K18: مستلم من اورا - بيد علي ) مساهمين
C19: 2000 | D19: =D18+B19-C19 -> -17000 | E19: استلام رملي من تايغر | I19: 10000 | J19: =J18+H19-I19 -> -209529 | K19: حساب بورصة
A20: 46233 | C20: 3000 | D20: =D19+B20-C20 -> -20000 | E20: استلام رملي من تايغر | G20: 46252 | I20: 29510 | J20: =J19+H20-I20 -> -239039 | K20: مكنات ايطاليا
D21: =D20+B21-C21 -> -20000 | J21: =J20+H21-I21 -> -239039
D22: =D21+B22-C22 -> -20000 | J22: =J21+H22-I22 -> -239039
D23: =D22+B23-C23 -> -20000 | J23: =J22+H23-I23 -> -239039
D24: =D23+B24-C24 -> -20000 | J24: =J23+H24-I24 -> -239039
D25: =D24+B25-C25 -> -20000 | J25: =J24+H25-I25 -> -239039
D26: =D25+B26-C26 -> -20000 | J26: =J25+H26-I26 -> -239039
D27: =D26+B27-C27 -> -20000 | J27: =J26+H27-I27 -> -239039
D28: =D27+B28-C28 -> -20000 | J28: =J27+H28-I28 -> -239039
D29: =D28+B29-C29 -> -20000 | J29: =J28+H29-I29 -> -239039
D30: =D29+B30-C30 -> -20000 | J30: =J29+H30-I30 -> -239039
D31: =D30+B31-C31 -> -20000 | J31: =J30+H31-I31 -> -239039
D32: =D31+B32-C32 -> -20000 | J32: =J31+H32-I32 -> -239039
... D567: =D566+B567-C567 -> -20000 | J567: =J566+H567-I567 -> -239039
D568: =D567+B568-C568 -> -20000 | G568: المجموع | H568: =SUM(H6:H567) -> 0 | I568: =SUM(I6:I567) -> 239039 | J568: =H568-I568 -> -239039
D569: =D568+B569-C569 -> -20000 | G569: الرصيد | H569: =H568-I568 -> -239039
D570: =D569+B570-C570 -> -20000
D571: =D570+B571-C571 -> -20000
D572: =D571+B572-C572 -> -20000
D573: =D572+B573-C573 -> -20000
D574: =D573+B574-C574 -> -20000
...

Sheet Mzen
A1: Paid from MAZEN
A2: دهب 995 | D2: =A1 -> Paid from MAZEN | G2: حساب دولار $ | J2: =A1 -> Paid from MAZEN
A3: من تاريخ :
A4: إلى تاريخ : | G4: إلى تاريخ :
A5: التاريخ | B5: مدفوع له | C5: مستلم منه | D5: الرصيد | E5: البيان | G5: التاريخ | H5: Debit | I5: Credit | J5: الرصيد | K5: البيان
A6: 46164 | C6: 536.9 | D6: =B6-C6 -> -536.9 | E6: مستلم رملي | G6: 45905 | I6: 1000 | J6: =H6-I6 -> -1000 | K6: دفعة بيد احمد اغا
A7: 46167 | B7: 53.14 | D7: =D6+B7-C7 -> -483.76 | E7: تسليم وسيم تميمي مشغول 18 // 70.51 غ | G7: 45911 | I7: 3000 | J7: =J6+H7-I7 -> -4000 | K7: دفعة بيد احمد اغا
A8: 46168 | C8: 700 | D8: =D7+B8-C8 -> -1183.76 | E8: مستلم رملي | G8: 45919 | I8: 3000 | J8: =J7+H8-I8 -> -7000 | K8: دفعة بيد احمد اغا
A9: 46176 | C9: 60.93 | D9: =D8+B9-C9 -> -1244.69 | E9: 80.84 مشغول//18// كادر ليرة | G9: 45938 | I9: 3000 | J9: =J8+H9-I9 -> -10000 | K9: دفعة بيد احمد اغا
A10: 46182 | B10: 1244.69 | D10: =D9+B10-C10 -> 0 | E10: تسليم مازن رملي | G10: 45940 | I10: 3000 | J10: =J9+H10-I10 -> -13000 | K10: دفعة بيد فارتان - الحداد
D11: =D10+B11-C11 -> 0 | G11: 45943 | I11: 465 | J11: =J10+H11-I11 -> -13465 | K11: دفعة بيد قاسم - زجاج
D12: =D11+B12-C12 -> 0 | G12: 45946 | I12: 1500 | J12: =J11+H12-I12 -> -14965 | K12: دفعة بيد محمد علوية من اصل 2750$
D13: =D12+B13-C13 -> 0 | G13: 45951 | I13: 3000 | J13: =J12+H13-I13 -> -17965 | K13: دفعة بيد احمد اغا
D14: =D13+B14-C14 -> 0 | G14: 45961 | I14: 3000 | J14: =J13+H14-I14 -> -20965 | K14: دفعة بيد احمد اغا
D15: =D14+B15-C15 -> 0 | G15: 45961 | I15: 12000 | J15: =J14+H15-I15 -> -32965 | K15: مدفوع من مازن اجار الورشة 1/9 لغاية 1/9/26
D16: =D15+B16-C16 -> 0 | G16: 45973 | I16: 1100 | J16: =J15+H16-I16 -> -34065 | K16: طاولات عدد 7
D17: =D16+B17-C17 -> 0 | G17: 45978 | I17: 8500 | J17: =J16+H17-I17 -> -42565 | K17: مكنات نقش و زخرفة
D18: =D17+B18-C18 -> 0 | G18: 45979 | I18: 1250 | J18: =J17+H18-I18 -> -43815 | K18: المنيوم
D19: =D18+B19-C19 -> 0 | G19: 45980 | I19: 850 | J19: =J18+H19-I19 -> -44665 | K19: بلانكو 1 طن
D20: =D19+B20-C20 -> 0 | G20: 45980 | I20: 477 | J20: =J19+H20-I20 -> -45142 | K20: axial fan
D21: =D20+B21-C21 -> 0 | G21: 45981 | I21: 300 | J21: =J20+H21-I21 -> -45442 | K21: خزنة من اصل 800
D22: =D21+B22-C22 -> 0 | G22: 45981 | I22: 5300 | J22: =J21+H22-I22 -> -50742 | K22: 10 مكيفات | N22: =11000*11650 -> 128150000
D23: =D22+B23-C23 -> 0 | G23: 45987 | I23: 800 | J23: =J22+H23-I23 -> -51542 | K23: خزنةتسكير حساب
D24: =D23+B24-C24 -> 0 | G24: 45987 | I24: 6520 | J24: =J23+H24-I24 -> -58062 | K24: مكنة سحب
D25: =D24+B25-C25 -> 0 | G25: 45987 | I25: 410 | J25: =J24+H25-I25 -> -58472 | K25: ونش لنقل الخزنة
D26: =D25+B26-C26 -> 0 | G26: 46000 | J26: =J25+H26-I26 -> -58472 | K26: شراء مكنات لمعمل الطابق الثاني
D27: =D26+B27-C27 -> 0 | G27: 45995 | I27: 300 | J27: =J26+H27-I27 -> -58772 | K27: جهاد ياسو
D28: =D27+B28-C28 -> 0 | G28: 45995 | I28: 1000 | J28: =J27+H28-I28 -> -59772 | K28: نجار مصطفى
D29: =D28+B29-C29 -> 0 | G29: 45995 | I29: 32.56 | J29: =J28+H29-I29 -> -59804.56 | K29: مفتا ح شق 2361 فاتورة
D30: =D29+B30-C30 -> 0 | G30: 45995 | I30: 280 | J30: =J29+H30-I30 -> -60084.56 | K30: ثمن عدة
D31: =D30+B31-C31 -> 0 | G31: 45996 | I31: 100 | J31: =J30+H31-I31 -> -60184.56 | K31: ونش لنق لمكنة
D32: =D31+B32-C32 -> 0 | G32: 45996 | I32: 109 | J32: =J31+H32-I32 -> -60293.56 | K32: عدة +غاز
D33: =D32+B33-C33 -> 0 | G33: 46007 | I33: 2100 | J33: =J32+H33-I33 -> -62393.56 | K33: خارتان الحداد
D34: =D33+B34-C34 -> 0 | G34: 46003 | I34: 60 | J34: =J33+H34-I34 -> -62453.56 | K34: مقص وزرديات و قضيب لحام
D35: =D34+B35-C35 -> 0 | G35: 46003 | I35: 230 | J35: =J34+H35-I35 -> -62683.56 | K35: نقل مكينات
D36: =D35+B36-C36 -> 0 | G36: 46003 | I36: 70 | J36: =J35+H36-I36 -> -62753.56 | K36: فليارات لمكنات السحب
D37: =D36+B37-C37 -> 0 | G37: 46009 | I37: 2310 | J37: =J36+H37-I37 -> -65063.56 | K37: جهاد ياسو
D38: =D37+B38-C38 -> 0 | G38: 46074 | I38: 12000 | J38: =J37+H38-I38 -> -77063.56 | K38: مكنات نزار دمغة
... D54: =D53+B54-C54 -> 0 | G54: 46150 | I54: 74736 | J54: =J53+H54-I54 -> -180014.56 | K54: ماكينات مازن
D55: =D54+B55-C55 -> 0 | G55: 46150 | I55: =36010-2726+54 -> 33338 | J55: =J54+H55-I55 -> -213352.56 | K55: مصاريف
...

Sheet خزنة رئيسية
A1: خزنة / رئيسي
A2: النوع | B2: دولار | C2: وزن
A3: صندوق دولار | B3: =دولار!H927 -> 39173
A4: دهب رملة 995 | C4: =دهب!B276 -> 0 | D4: =C4 -> 0
A5: فضة روباص | C5: =فضة!B131 -> 6675.18
A6: Alloy Cast | C6: ='Alloy Cast'!B104 -> 2733.44
A7: Alloy سحب | C7: ='Alloy سحب'!B116 -> 2541.15
A8: دهب كسر 18 - صب | C8: ='كسر 18 صب'!B150 -> 0 | D8: =C8*748/995 -> 0
A9: دهب كسر 18 - سحب | C9: ='كسر 18 سحب'!B104 -> 0 | D9: =C9*748/995 -> 0
A10: دهب كسر 21 - صب | C10: ='كسر 21 صب'!B104 -> 0 | D10: =C10*873/995 -> 0
A11: دهب كسر 21 - سحب | C11: ='كسر 21 سحب'!B104 -> 0 | D11: =C11*873/995 -> 0
A12: مشغول 18 | B12: ='مشغول 18'!H613 -> -160727 | C12: ='مشغول 18'!B611 -> 0 | D12: =C12*748/995 -> 0
A13: مشغول 21 | C13: ='مشغول 21'!B104 -> 0 | D13: =C13*873/995 -> 0
A14: K18 - 740 | B14: ='K18'!B150 -> 0 | D14: =B14*0.74 -> 0
A15: K22 - 905 | B15: ='K22'!B104 -> 0 | D15: =B15*0.905 -> 0
A16: K21 - 865 | B16: ='K21'!B118 -> 0 | D16: =B16*0.865 -> 0
A18: مجموع الدهب | C18: =SUM(D4:D16) -> 0

Sheet دولار
A1: Pro
A2: دهب 995 | D2: =A1 -> Pro | G2: حساب دولار $
A3: من تاريخ :
A4: إلى تاريخ : | G4: إلى تاريخ :
A5: التاريخ | B5: مدفوع له | C5: مستلم منه | D5: الرصيد | E5: البيان | G5: التاريخ | H5: دخول | I5: خروج | J5: الرصيد | K5: البيان
D6: =B6-C6 -> 0 | G6: 46157 | H6: 678 | J6: =H6-I6 -> 678 | K6: مستلم من اجور 18
D7: =D6+B7-C7 -> 0 | G7: 46164 | H7: 1180 | J7: =J6+H7-I7 -> 1858 | K7: مستلم من مساهمين احمد كنجو -من اورا
D8: =D7+B8-C8 -> 0 | G8: 46164 | H8: 240 | J8: =J7+H8-I8 -> 2098 | K8: اجور الزاوية غ32.34 // 18
D9: =D8+B9-C9 -> 0 | G9: 46164 | I9: 660 | J9: =J8+H9-I9 -> 1438 | K9: مدفوع لمازن
D10: =D9+B10-C10 -> 0 | G10: 46164 | I10: 100 | J10: =J9+H10-I10 -> 1338 | K10: ناتو سحب عالمعاش
D11: =D10+B11-C11 -> 0 | G11: 46164 | I11: 100 | J11: =J10+H11-I11 -> 1238 | K11: فتوح سحب عالمعاش
D12: =D11+B12-C12 -> 0 | G12: 46164 | I12: 500 | J12: =J11+H12-I12 -> 738 | K12: جهاد سحب عالمعاش
D13: =D12+B13-C13 -> 0 | G13: 46167 | I13: 49.5 | J13: =J12+H13-I13 -> 688.5 | K13: شراء عدة هاروت ف // 768
D14: =D13+B14-C14 -> 0 | G14: 46167 | I14: 5.5 | J14: =J13+H14-I14 -> 683 | K14: شراء عدة هاروت ف // مكتبة حسون
D15: =D14+B15-C15 -> 0 | G15: 46167 | I15: 10 | J15: =J14+H15-I15 -> 673 | K15: شمع من الرضوان
D16: =D15+B16-C16 -> 0 | G16: 46167 | I16: 300 | J16: =J15+H16-I16 -> 373 | K16: شراء اللوي سحب
D17: =D16+B17-C17 -> 0 | G17: 46168 | I17: 30 | J17: =J16+H17-I17 -> 343 | K17: مخرطة بيد جهاد
D18: =D17+B18-C18 -> 0 | G18: 46168 | H18: 4940 | J18: =J17+H18-I18 -> 5283 | K18: محمد عيساوي
D19: =D18+B19-C19 -> 0 | G19: 46168 | I19: 250 | J19: =J18+H19-I19 -> 5033 | K19: جهاد سحب عالمعاش
D20: =D19+B20-C20 -> 0 | G20: 46168 | I20: 120 | J20: =J19+H20-I20 -> 4913 | K20: مصروف فاتورة سيتي ستار
D21: =D20+B21-C21 -> 0 | G21: 46174 | I21: 3650 | J21: =J20+H21-I21 -> 1263 | K21: معاشات
D22: =D21+B22-C22 -> 0 | G22: 46174 | I22: 385 | J22: =J21+H22-I22 -> 878 | K22: سلندر جفصين
D23: =D22+B23-C23 -> 0 | G23: 46174 | I23: 12 | J23: =J22+H23-I23 -> 866 | K23: قالب كوتشوك سيلكون
D24: =D23+B24-C24 -> 0 | G24: 46174 | I24: 124 | J24: =J23+H24-I24 -> 742 | K24: مازن غراض قاروط
D25: =D24+B25-C25 -> 0 | G25: 46174 | I25: 100 | J25: =J24+H25-I25 -> 642 | K25: علي غراض قاروط
D26: =D25+B26-C26 -> 0 | G26: 46174 | I26: 12 | J26: =J25+H26-I26 -> 630 | K26: فاتورة habtraco brass 6mm
D27: =D26+B27-C27 -> 0 | G27: 46175 | H27: 2600 | J27: =J26+H27-I27 -> 3230 | K27: مستلم كاش من مازن
D28: =D27+B28-C28 -> 0 | G28: 46175 | I28: 2600 | J28: =J27+H28-I28 -> 630 | K28: مدفوع قولب غورميت
D29: =D28+B29-C29 -> 0 | G29: 46175 | H29: 500 | J29: =J28+H29-I29 -> 1130 | K29: مستلم كاش من علي
D30: =D29+B30-C30 -> 0 | G30: 46175 | I30: 625 | J30: =J29+H30-I30 -> 505 | K30: مجموع فواتير مشتريات هاروط
D31: =D30+B31-C31 -> 0 | G31: 46175 | H31: 500 | J31: =J30+H31-I31 -> 1005 | K31: مستلم كاش من مازن
D32: =D31+B32-C32 -> 0 | G32: 46175 | I32: 10 | J32: =J31+H32-I32 -> 995 | K32: مياه
D33: =D32+B33-C33 -> 0 | G33: 46176 | I33: 200 | J33: =J32+H33-I33 -> 795 | K33: تكملة معاش ناتو
D34: =D33+B34-C34 -> 0 | G34: 46176 | I34: =25+24+120+12 -> 181 | J34: =J33+H34-I34 -> 614 | K34: مجموع فواتير مشتريات هاروط
D35: =D34+B35-C35 -> 0 | G35: 46177 | H35: 598 | J35: =J34+H35-I35 -> 1212 | K35: فاتورة 002803 محمد سعيفان
D36: =D35+B36-C36 -> 0 | G36: 46177 | H36: 474 | J36: =J35+H36-I36 -> 1686 | K36: فاتورة 002804 محمد سعيفان
D37: =D36+B37-C37 -> 0 | G37: 46177 | H37: 643 | J37: =J36+H37-I37 -> 2329 | K37: فاتورة 002805 محمد عمار
D38: =D37+B38-C38 -> 0 | G38: 46177 | I38: 115 | J38: =J37+H38-I38 -> 2214 | K38: قوالب سليكون
D39: =D38+B39-C39 -> 0 | G39: 46177 | I39: 165 | J39: =J38+H39-I39 -> 2049 | K39: شراء حجار صمباط
G40: 46178 | I40: 130 | J40: =J39+H40-I40 -> 1919 | K40: سلفة vicken
...

Sheet دهب
A2: دهب 995
A3: من تاريخ :
A4: إلى تاريخ :
A5: التاريخ | B5: دخول | C5: خروج | D5: الرصيد | E5: البيان
B6: 74.31 | D6: =B6-C6 -> 74.31
B7: 986.31 | D7: =D6+B7-C7 -> 1060.62 | E7: مستلم من احمد
C8: 834.16 | D8: =D7+B8-C8 -> 226.46 | E8: تسليم شجر عدد 4
A9: 46161 | B9: 145.96 | D9: =D8+B9-C9 -> 372.42
A10: 46161 | C10: 150 | D10: =D9+B10-C10 -> 222.42 | E10: تسليم ناتو 199.53غ // 18 للسحب
A11: 46163 | C11: 200 | D11: =D10+B11-C11 -> 22.42 | E11: للسحب // 482.74 غ
A12: 46164 | B12: 536.9 | D12: =D11+B12-C12 -> 559.32 | E12: مستلم من مازن
A13: 46164 | C13: 100.23 | D13: =D12+B13-C13 -> 459.09 | E13: تسليم لللحام رملي
A14: 46164 | C14: 400 | D14: =D13+B14-C14 -> 59.09 | E14: للسحب // غ 532.09 //18
A15: 46168 | B15: 700 | D15: =D14+B15-C15 -> 759.09 | E15: مستلم من مازن
A16: 46168 | C16: 708.7 | D16: =D15+B16-C16 -> 50.39 | E16: تسليم شجر عدد 4
A17: 46177 | B17: 689.3 | D17: =D16+B17-C17 -> 739.69 | E17: سبيكة سحب صب تبديل 915.81
A18: 46177 | B18: 92.12 | D18: =D17+B18-C18 -> 831.81 | E18: فاتورة 002805 محمد عمار
A19: 46178 | B19: 600 | D19: =D18+B19-C19 -> 1431.81 | E19: استلام رملي من تايغر
A20: 46181 | B20: 4653.29 | D20: =D19+B20-C20 -> 6085.1 | E20: استلام رملي من تايغر
A21: 46181 | C21: 1321.67 | D21: =D20+B21-C21 -> 4763.43 | E21: شجر عدد 6
A22: 46181 | B22: 29.04 | D22: =D21+B22-C22 -> 4792.47 | E22: تسليم مازن بلاك // 38.53 // 18
A23: 46182 | C23: 1244.69 | D23: =D22+B23-C23 -> 3547.78 | E23: تسليم مازن رملي
A24: 46182 | C24: 500.05 | D24: =D23+B24-C24 -> 3047.73 | E24: للسحب 665.17
A25: 46182 | C25: 20.27 | D25: =D24+B25-C25 -> 3027.46 | E25: مستلم محابس من عيسى
A26: 46182 | C26: 81.19 | D26: =D25+B26-C26 -> 2946.27 | E26: مستلم محابس من عيسى
A27: 46182 | C27: 64.57 | D27: =D26+B27-C27 -> 2881.7 | E27: مستلم سنسال فورسا
A28: 46182 | C28: 22.03 | D28: =D27+B28-C28 -> 2859.67 | E28: مستلم سنسال فورسا
A29: 46183 | C29: 1138.83 | D29: =D28+B29-C29 -> 1720.84 | E29: شجر عدد 5
A30: 46184 | B30: 88.54 | D30: =D29+B30-C30 -> 1809.38 | E30: ف 002812 // ريم كجوج
A31: 46185 | B31: 69.79 | D31: =D30+B31-C31 -> 1879.17 | E31: ف 002810 // محمد عمار
A32: 46188 | C32: 393.01 | D32: =D31+B32-C32 -> 1486.16 | E32: صب شجر عدد 2
A33: 46188 | C33: 50.02 | D33: =D32+B33-C33 -> 1436.14 | E33: قفل
A34: 46190 | B34: 240.88 | D34: =D33+B34-C34 -> 1677.02 | E34: ف 002816 // عطولي
A35: 46190 | B35: 34.84 | D35: =D34+B35-C35 -> 1711.86 | E35: ف 002817 // تايغر
A36: 46190 | C36: 37.37 | D36: =D35+B36-C36 -> 1674.49 | E36: تبديل على كسر
A37: 46190 | B37: 31.07 | D37: =D36+B37-C37 -> 1705.56 | E37: شراء
A38: 46196 | C38: 1321.87 | D38: =D37+B38-C38 -> 383.69 | E38: صب شجر عدد 5
A39: 46197 | B39: 60 | D39: =D38+B39-C39 -> 443.69 | E39: شراء
A40: 46198 | B40: 120.15 | D40: =D39+B40-C40 -> 563.84 | E40: علي زهور
A41: 46198 | C41: 53.49 | D41: =D40+B41-C41 -> 510.35 | E41: فورسا
...

Sheet فضة
A2: فضة
A3: من تاريخ :
A4: إلى تاريخ :
A5: التاريخ | B5: دخول | C5: خروج | D5: الرصيد | E5: البيان
A6: 46157 | B6: 1000 | D6: =B6-C6 -> 1000 | E6: من المساهمين
A7: 46157 | C7: 574.51 | D7: =D6+B7-C7 -> 425.49
A8: 46161 | C8: 137.72 | D8: =D7+B8-C8 -> 287.77 | E8: شجر عدد 4
A9: 46161 | C9: 25.53 | D9: =D8+B9-C9 -> 262.24 | E9: تسليم ناتو 199.53غ للسحب
A10: 46163 | C10: 34.04 | D10: =D9+B10-C10 -> 228.2
A11: 46164 | C11: 68.08 | D11: =D10+B11-C11 -> 160.12
A12: 46167 | B12: 7000 | D12: =D11+B12-C12 -> 7160.12 | E12: من المساهمين المجموع 8 كيلو
C13: 117.01 | D13: =D12+B13-C13 -> 7043.11 | E13: شجر عدد 4
A14: 46181 | C14: 218.21 | D14: =D13+B14-C14 -> 6824.9
A15: 46182 | C15: 80 | D15: =D14+B15-C15 -> 6744.9
A16: 46183 | C16: 188.03 | D16: =D15+B16-C16 -> 6556.87
A17: 46188 | C17: 64.89 | D17: =D16+B17-C17 -> 6491.98
A18: 46196 | C18: 218.25 | D18: =D17+B18-C18 -> 6273.73 | E18: شجر عدد 5
A19: 46198 | C19: 29.81 | D19: =D18+B19-C19 -> 6243.92 | E19: شجر عدد 6
A20: 46205 | C20: 599.72 | D20: =D19+B20-C20 -> 5644.2 | E20: شجر عدد 7
A21: 46206 | C21: 60.8 | D21: =D20+B21-C21 -> 5583.4 | E21: للصب 505.48
A22: 46211 | C22: 209.38 | D22: =D21+B22-C22 -> 5374.02 | E22: شجر عدد 6
A23: 46217 | C23: 185.14 | D23: =D22+B23-C23 -> 5188.88 | E23: شجر عدد 6
A24: 46218 | C24: 160 | D24: =D23+B24-C24 -> 5028.88 | E24: سحب
A25: 46230 | C25: 27.94 | D25: =D24+B25-C25 -> 5000.94
A26: 46230 | C26: 221.31 | D26: =D25+B26-C26 -> 4779.63
A27: 46230 | C27: 120 | D27: =D26+B27-C27 -> 4659.63
A28: 46230 | C28: 12 | D28: =D27+B28-C28 -> 4647.63
A29: 46230 | C29: 176.66 | D29: =D28+B29-C29 -> 4470.97
C30: 48 | D30: =D29+B30-C30 -> 4422.97
C31: 16 | D31: =D30+B31-C31 -> 4406.97
C32: 289.26 | D32: =D31+B32-C32 -> 4117.71
C33: 16 | D33: =D32+B33-C33 -> 4101.71
C34: 853.24 | D34: =D33+B34-C34 -> 3248.47
C35: 165.1 | D35: =D34+B35-C35 -> 3083.37
C36: 190.74 | D36: =D35+B36-C36 -> 2892.63
C37: 72.12 | D37: =D36+B37-C37 -> 2820.51
C38: 522.45 | D38: =D37+B38-C38 -> 2298.06
C39: 210 | D39: =D38+B39-C39 -> 2088.06
C40: 122.3 | D40: =D39+B40-C40 -> 1965.76
C41: 115.37 | D41: =D40+B41-C41 -> 1850.39
...

Sheet Alloy Cast
A2: Alloy Cast
A3: من تاريخ :
A4: إلى تاريخ :
A5: التاريخ | B5: مدفوع له | C5: مستلم منه | D5: الرصيد | E5: البيان
B6: 3000 | D6: =B6-C6 -> 3000
C7: 376.48 | D7: =D6+B7-C7 -> 2623.52
A8: 46161 | C8: 137.72 | D8: =D7+B8-C8 -> 2485.8 | E8: شجر عدد 4
A9: 46168 | C9: 117.01 | D9: =D8+B9-C9 -> 2368.79 | E9: شجر عدد 4
A10: 46181 | C10: 218.21 | D10: =D9+B10-C10 -> 2150.58 | E10: شجر عدد 6
A11: 46183 | C11: 188.03 | D11: =D10+B11-C11 -> 1962.55
A12: 46188 | C12: 64.89 | D12: =D11+B12-C12 -> 1897.66
A13: 46196 | C13: 218.25 | D13: =D12+B13-C13 -> 1679.41 | E13: شجر عدد 5
A14: 46198 | C14: 29.81 | D14: =D13+B14-C14 -> 1649.6 | E14: شجر عدد 6
A15: 46205 | C15: 599.72 | D15: =D14+B15-C15 -> 1049.88 | E15: شجر عدد 7
A16: 46211 | C16: 209.38 | D16: =D15+B16-C16 -> 840.5 | E16: شجر عدد 6
C17: 185.14 | D17: =D16+B17-C17 -> 655.36 | E17: شجر عدد 6
A18: 46230 | C18: 221.31 | D18: =D17+B18-C18 -> 434.05 | E18: شجر عدد 6
A19: 46230 | C19: 176.66 | D19: =D18+B19-C19 -> 257.39 | E19: شجر عدد 6
A20: 46238 | C20: 257.39 | D20: =D19+B20-C20 -> 0
A21: 46247 | B21: 5000 | D21: =D20+B21-C21 -> 5000 | E21: مستلم
A22: 46247 | C22: 190.74 | D22: =D21+B22-C22 -> 4809.26
A23: 46251 | C23: 522.45 | D23: =D22+B23-C23 -> 4286.81
C24: 210 | D24: =D23+B24-C24 -> 4076.81
C25: 115.37 | D25: =D24+B25-C25 -> 3961.44
C26: 80.25 | D26: =D25+B26-C26 -> 3881.19
C27: 225.88 | D27: =D26+B27-C27 -> 3655.31
C28: 92.46 | D28: =D27+B28-C28 -> 3562.85
C29: 194.71 | D29: =D28+B29-C29 -> 3368.14
C30: 168.03 | D30: =D29+B30-C30 -> 3200.11
C31: 118.88 | D31: =D30+B31-C31 -> 3081.23
C32: 99.01 | D32: =D31+B32-C32 -> 2982.22
C33: 99.69 | D33: =D32+B33-C33 -> 2882.53
C34: 149.09 | D34: =D33+B34-C34 -> 2733.44
D35: =D34+B35-C35 -> 2733.44
D36: =D35+B36-C36 -> 2733.44
D37: =D36+B37-C37 -> 2733.44
D38: =D37+B38-C38 -> 2733.44
D39: =D38+B39-C39 -> 2733.44
D40: =D39+B40-C40 -> 2733.44
D41: =D40+B41-C41 -> 2733.44
...

Sheet Alloy سحب
A2: Alloy سحب
A3: من تاريخ :
A4: إلى تاريخ :
A5: التاريخ | B5: دخول | C5: خروج | D5: الرصيد | E5: البيان
A6: 46157 | B6: 1000 | D6: =B6-C6 -> 1000
C7: 203.33 | D7: =D6+B7-C7 -> 796.67
A8: 46161 | C8: 24 | D8: =D7+B8-C8 -> 772.67
A9: 46163 | C9: 32 | D9: =D8+B9-C9 -> 740.67
A10: 46164 | C10: 64 | D10: =D9+B10-C10 -> 676.67
A11: 46182 | C11: 85.11 | D11: =D10+B11-C11 -> 591.56
B12: 2000 | D12: =D11+B12-C12 -> 2591.56
A13: 46206 | C13: 64.68 | D13: =D12+B13-C13 -> 2526.88 | E13: للصب 505.48
A14: 46210 | C14: 11 | D14: =D13+B14-C14 -> 2515.88
A15: 46218 | C15: 170.21 | D15: =D14+B15-C15 -> 2345.67
C16: 55.89 | D16: =D15+B16-C16 -> 2289.78
C17: 2.8 | D17: =D16+B17-C17 -> 2286.98
C18: 11.64 | D18: =D17+B18-C18 -> 2275.34
C19: 127.66 | D19: =D18+B19-C19 -> 2147.68
C20: 12.77 | D20: =D19+B20-C20 -> 2134.91
C21: 51.06 | D21: =D20+B21-C21 -> 2083.85
C22: 17.02 | D22: =D21+B22-C22 -> 2066.83
C23: 8.8 | D23: =D22+B23-C23 -> 2058.03
C24: 31.87 | D24: =D23+B24-C24 -> 2026.16
C25: 17.02 | D25: =D24+B25-C25 -> 2009.14
C26: 853.24 | D26: =D25+B26-C26 -> 1155.9
A27: 46245 | B27: 2000 | D27: =D26+B27-C27 -> 3155.9
A28: 46247 | C28: 165.1 | D28: =D27+B28-C28 -> 2990.8
A29: 46248 | C29: 76.72 | D29: =D28+B29-C29 -> 2914.08
C30: 130.11 | D30: =D29+B30-C30 -> 2783.97
C31: 34.04 | D31: =D30+B31-C31 -> 2749.93
C32: 14.85 | D32: =D31+B32-C32 -> 2735.08
C33: 65.27 | D33: =D32+B33-C33 -> 2669.81
C34: 128.66 | D34: =D33+B34-C34 -> 2541.15
D35: =D34+B35-C35 -> 2541.15
D36: =D35+B36-C36 -> 2541.15
D37: =D36+B37-C37 -> 2541.15
D38: =D37+B38-C38 -> 2541.15
D39: =D38+B39-C39 -> 2541.15
D40: =D39+B40-C40 -> 2541.15
D41: =D40+B41-C41 -> 2541.15
...

Sheet كسر 18 صب
A2: كسر 750 | D2: صب
A3: من تاريخ :
A4: إلى تاريخ :
A5: التاريخ | B5: دخول | C5: خروج | D5: الرصيد | E5: البيان
B6: 1727.63 | D6: =B6-C6 -> 1727.63
A7: 46161 | C7: 1670.91 | D7: =D6+B7-C7 -> 56.72 | E7: شجر عدد 4
A8: 46163 | B8: 216.7 | D8: =D7+B8-C8 -> 273.42 | E8: استلام كسر 18 //
A9: 46163 | C9: 216.7 | D9: =D8+B9-C9 -> 56.72 | E9: للسحب // 482.74 غ
A10: 46168 | B10: 1958.59 | D10: =D9+B10-C10 -> 2015.31 | E10: استلام كسر 18 // صب
A11: 46168 | C11: 1417.09 | D11: =D10+B11-C11 -> 598.22 | E11: شجر عدد 4
A12: 46176 | B12: 2439.91 | D12: =D11+B12-C12 -> 3038.13 | E12: استلام كسر 18 // صب
A13: 46181 | C13: 2642.76 | D13: =D12+B13-C13 -> 395.37
A14: 46183 | B14: 3388.22 | D14: =D13+B14-C14 -> 3783.59 | E14: استلام كسر 18 // صب
A15: 46183 | C15: 2277.17 | D15: =D14+B15-C15 -> 1506.42 | E15: شجر عدد 5
A16: 46188 | C16: 785.84 | D16: =D15+B16-C16 -> 720.58 | E16: صب شجر عدد 2
A17: 46188 | B17: 3065.45 | D17: =D16+B17-C17 -> 3786.03 | E17: استلام كسر 18 // صب
A18: 46189 | C18: 3740.17 | D18: =D17+B18-C18 -> 45.86 | E18: صب شجر عدد 5
A19: 46196 | B19: 3549.45 | D19: =D18+B19-C19 -> 3595.31 | E19: استلام كسر 18 // صب
A20: 46196 | C20: 2643.17 | D20: =D19+B20-C20 -> 952.14 | E20: صب شجر عدد 5
A21: 46198 | B21: 3093.16 | D21: =D20+B21-C21 -> 4045.3 | E21: استلام كسر 18 // صب
A22: 46198 | C22: 3978.19 | D22: =D21+B22-C22 -> 67.11 | E22: صب شجر عدد 6
A23: 46198 | B23: 4251.66 | D23: =D22+B23-C23 -> 4318.77 | E23: استلام كسر 18 // صب
A24: 46211 | C24: 2535.79 | D24: =D23+B24-C24 -> 1782.98 | E24: صب شجر عدد 6
A25: 46217 | B25: 3116.09 | D25: =D24+B25-C25 -> 4899.07 | E25: استلام كسر 18 // صب
A26: 46217 | C26: 2242.19 | D26: =D25+B26-C26 -> 2656.88 | E26: صب شجر عدد 6
A27: 46223 | B27: 2967.17 | D27: =D26+B27-C27 -> 5624.05 | E27: استلام كسر 18 // صب
A28: 46223 | B28: 2562.54 | D28: =D27+B28-C28 -> 8186.59 | E28: استلام كسر 18 // صب
A29: 46224 | C29: 2328.26 | D29: =D28+B29-C29 -> 5858.33
A30: 46224 | C30: 4000.95 | D30: =D29+B30-C30 -> 1857.38
A31: 46224 | C31: 613.19 | D31: =D30+B31-C31 -> 1244.19
A32: 46230 | B32: 3614.99 | D32: =D31+B32-C32 -> 4859.18 | E32: استلام كسر 18 // صب
A33: 46230 | C33: 2680.29 | D33: =D32+B33-C33 -> 2178.89 | E33: صب شجر عدد 6
A34: 46230 | B34: 3821.1 | D34: =D33+B34-C34 -> 5999.99 | E34: استلام كسر 18 // صب
A35: 46230 | C35: 3075.16 | D35: =D34+B35-C35 -> 2924.83 | E35: صب شجر عدد 6
A36: 46232 | B36: 106.56 | D36: =D35+B36-C36 -> 3031.39 | E36: استلام كسر 18 // صب
A37: 46237 | B37: 3758.53 | D37: =D36+B37-C37 -> 6789.92 | E37: استلام كسر 18 // صب
C38: 3503.15 | D38: =D37+B38-C38 -> 3286.77 | E38: صب شجر عدد 6
B39: 2955.87 | D39: =D38+B39-C39 -> 6242.64
B40: 527.68 | D40: =D39+B40-C40 -> 6770.32
C41: 271.01 | D41: =D40+B41-C41 -> 6499.31 | E41: للصب
...

Sheet كسر 18 سحب
A2: كسر 750 | D2: سحب
A3: من تاريخ :
A4: إلى تاريخ :
A5: التاريخ | B5: دخول | C5: خروج | D5: الرصيد | E5: البيان
D6: =B6-C6 -> 0
D7: =D6+B7-C7 -> 0
D8: =D7+B8-C8 -> 0
D9: =D8+B9-C9 -> 0
D10: =D9+B10-C10 -> 0
D11: =D10+B11-C11 -> 0
D12: =D11+B12-C12 -> 0
D13: =D12+B13-C13 -> 0
D14: =D13+B14-C14 -> 0
D15: =D14+B15-C15 -> 0
D16: =D15+B16-C16 -> 0
D17: =D16+B17-C17 -> 0
D18: =D17+B18-C18 -> 0
... D102: =D101+B102-C102 -> 0
A103: المجموع | B103: =SUM(B6:B102) -> 0 | C103: =SUM(C6:C102) -> 0 | D103: =B103-C103 -> 0
A104: الرصيد | B104: =B103-C103 -> 0

Sheet كسر 21 صب
A2: كسر 875 | D2: صب
A3: من تاريخ :
A4: إلى تاريخ :
A5: التاريخ | B5: مدفوع له | C5: مستلم منه | D5: الرصيد | E5: البيان
D6: =B6-C6 -> 0
D7: =D6+B7-C7 -> 0
D8: =D7+B8-C8 -> 0
D9: =D8+B9-C9 -> 0
D10: =D9+B10-C10 -> 0
D11: =D10+B11-C11 -> 0
D12: =D11+B12-C12 -> 0
D13: =D12+B13-C13 -> 0
D14: =D13+B14-C14 -> 0
D15: =D14+B15-C15 -> 0
D16: =D15+B16-C16 -> 0
D17: =D16+B17-C17 -> 0
D18: =D17+B18-C18 -> 0
... D102: =D101+B102-C102 -> 0
A103: المجموع | B103: =SUM(B6:B102) -> 0 | C103: =SUM(C6:C102) -> 0 | D103: =B103-C103 -> 0
A104: الرصيد | B104: =B103-C103 -> 0

Sheet كسر 21 سحب
A2: كسر 875 | D2: سحب
A3: من تاريخ :
A4: إلى تاريخ :
A5: التاريخ | B5: مدفوع له | C5: مستلم منه | D5: الرصيد | E5: البيان
D6: =B6-C6 -> 0
D7: =D6+B7-C7 -> 0
D8: =D7+B8-C8 -> 0
D9: =D8+B9-C9 -> 0
D10: =D9+B10-C10 -> 0
D11: =D10+B11-C11 -> 0
D12: =D11+B12-C12 -> 0
D13: =D12+B13-C13 -> 0
D14: =D13+B14-C14 -> 0
D15: =D14+B15-C15 -> 0
D16: =D15+B16-C16 -> 0
D17: =D16+B17-C17 -> 0
D18: =D17+B18-C18 -> 0
... D102: =D101+B102-C102 -> 0
A103: المجموع | B103: =SUM(B6:B102) -> 0 | C103: =SUM(C6:C102) -> 0 | D103: =B103-C103 -> 0
A104: الرصيد | B104: =B103-C103 -> 0

Sheet مشغول 21
A2: مشغول 875 | G2: اجور دولار
A3: من تاريخ :
A4: إلى تاريخ : | G4: إلى تاريخ :
A5: التاريخ | B5: مستلم من تصنيع | C5: تسليم زبائن | D5: الرصيد | E5: البيان | G5: التاريخ | H5: تسليم | I5: استلام | J5: الرصيد | K5: البيان
A6: 46178 | B6: 389.45 | D6: =B6-C6 -> 389.45 | E6: مستلم من اورا مشغول 21 | G6: 46226 | I6: 230 | J6: =H6-I6 -> -230 | K6: ف 002918 // نور حسون
A7: 46225 | B7: 355.74 | D7: =D6+B7-C7 -> 745.19 | E7: محابس | G7: 46230 | I7: 1334 | J7: =J6+H7-I7 -> -1564 | K7: ف 002920 // محمد قنديل
A8: 46226 | C8: 70.77 | D8: =D7+B8-C8 -> 674.42 | E8: ف 002918 // نور حسون | G8: 46234 | I8: 25 | J8: =J7+H8-I8 -> -1589 | K8: مبيع
A9: 46230 | C9: 355.74 | D9: =D8+B9-C9 -> 318.68 | E9: ف 002920 // محمد قنديل | J9: =J8+H9-I9 -> -1589
A10: 46234 | C10: 14.57 | D10: =D9+B10-C10 -> 304.11 | E10: مبيع | J10: =J9+H10-I10 -> -1589
A11: 46247 | C11: 223.76 | D11: =D10+B11-C11 -> 80.35 | E11: تعديل جردة | J11: =J10+H11-I11 -> -1589
A12: 46268 | B12: 64 | D12: =D11+B12-C12 -> 144.35 | E12: 8 ليرات | J12: =J11+H12-I12 -> -1589
A13: 46286 | C13: 24 | D13: =D12+B13-C13 -> 120.35 | E13: مبيع 3 ليرات | J13: =J12+H13-I13 -> -1589
C14: 120.35 | D14: =D13+B14-C14 -> 0 | J14: =J13+H14-I14 -> -1589
D15: =D14+B15-C15 -> 0 | J15: =J14+H15-I15 -> -1589
D16: =D15+B16-C16 -> 0 | J16: =J15+H16-I16 -> -1589
D17: =D16+B17-C17 -> 0 | J17: =J16+H17-I17 -> -1589
D18: =D17+B18-C18 -> 0 | J18: =J17+H18-I18 -> -1589
D19: =D18+B19-C19 -> 0 | J19: =J18+H19-I19 -> -1589
D20: =D19+B20-C20 -> 0 | J20: =J19+H20-I20 -> -1589
D21: =D20+B21-C21 -> 0 | J21: =J20+H21-I21 -> -1589
D22: =D21+B22-C22 -> 0 | J22: =J21+H22-I22 -> -1589
D23: =D22+B23-C23 -> 0 | J23: =J22+H23-I23 -> -1589
D24: =D23+B24-C24 -> 0 | J24: =J23+H24-I24 -> -1589
D25: =D24+B25-C25 -> 0 | J25: =J24+H25-I25 -> -1589
D26: =D25+B26-C26 -> 0 | J26: =J25+H26-I26 -> -1589
... D102: =D101+B102-C102 -> 0 | J102: =J101+H102-I102 -> -1589
A103: المجموع | B103: =SUM(B6:B102) -> 809.19 | C103: =SUM(C6:C102) -> 809.19 | D103: =B103-C103 -> 0 | J103: =J102+H103-I103 -> -1589
A104: الرصيد | B104: =B103-C103 -> 0 | J104: =J103+H104-I104 -> -1589
G105: المجموع | H105: =SUM(H6:H104) -> 0 | I105: =SUM(I6:I104) -> 1589 | J105: =H105-I105 -> -1589
G106: الرصيد | H106: =H105-I105 -> -1589
J305: =H106 -> -1589 | K305: الرصيد

Sheet مشغول 18
A2: مشغول 750 | G2: اجور دولار
A3: من تاريخ :
A4: إلى تاريخ : | G4: إلى تاريخ :
A5: التاريخ | B5: مستلم من تصنيع | C5: تسليم زبائن | D5: الرصيد | E5: البيان | G5: التاريخ | H5: تسليم | I5: استلام | J5: الرصيد | K5: البيان
A6: 46157 | B6: 582.34 | D6: =B6-C6 -> 582.34 | E6: مستلم من ناتو مشغول 18 | G6: 46161 | I6: 678 | J6: =H6-I6 -> -678 | K6: تسليم محمد محابس 18 // 193.64 غ
A7: 46157 | B7: 193.64 | D7: =D6+B7-C7 -> 775.98 | E7: مستلم من ناتو مشغول 18 محابس | I7: 240 | J7: =J6+H7-I7 -> -918 | K7: تسليم الزاوية 32.34 غ //18
A8: 46161 | C8: 193.64 | D8: =D7+B8-C8 -> 582.34 | E8: تسليم محمد محابس 18 | I8: 317 | J8: =J7+H8-I8 -> -1235 | K8: تسليم وسيم تميمي مشغول 18 // 70.51 غ
A9: 46164 | C9: 32.34 | D9: =D8+B9-C9 -> 550 | E9: تسليم الزاوية | G9: 46168 | I9: 320 | J9: =J8+H9-I9 -> -1555 | K9: تسليم احمد كنجو مشغول 18
A10: 46167 | C10: 70.51 | D10: =D9+B10-C10 -> 479.49 | E10: تسليم وسيم تميمي مشغول 18 // 70.51 غ | G10: 46168 | I10: 258 | J10: =J9+H10-I10 -> -1813 | K10: تسليم محمد عيساوي مشغول 18
A11: 46167 | B11: 26.08 | D11: =D10+B11-C11 -> 505.57 | E11: مستلم من ناتو مشغول 18 | G11: 46177 | I11: 598 | J11: =J10+H11-I11 -> -2411 | K11: فاتورة 002803 محمد سعيفان
A12: 46168 | B12: 38.97 | D12: =D11+B12-C12 -> 544.54 | E12: مشغول 18 // 38.97 غ | G12: 46177 | I12: 117 | J12: =J11+H12-I12 -> -2528 | K12: فاتورة 002804 محمد سعيفان
A13: 46168 | C13: 42.75 | D13: =D12+B13-C13 -> 501.79 | E13: تسليم احمد كنجو مشغول 18 | G13: 46177 | I13: 643 | J13: =J12+H13-I13 -> -3171 | K13: فاتورة 002805 محمد عمار
A14: 46168 | B14: 31.31 | D14: =D13+B14-C14 -> 533.1 | E14: مستلم من ناتو مشغول 18 | G14: 46182 | I14: 193 | J14: =J13+H14-I14 -> -3364 | K14: تسليم مازن بلاك // 38.53 //
A15: 46168 | C15: 42.9 | D15: =D14+B15-C15 -> 490.2 | E15: تسليم محمد عيساوي مشغول 18 | G15: 46182 | H15: 108 | J15: =J14+H15-I15 -> -3256 | K15: مستلم محابس من عيسى
A16: 46176 | B16: 162.3 | D16: =D15+B16-C16 -> 652.5 | E16: مستلم من ناتو مشغول 18 | G16: 46182 | H16: 430 | J16: =J15+H16-I16 -> -2826 | K16: مستلم محابس من عيسى
A17: 46176 | B17: 22.64 | D17: =D16+B17-C17 -> 675.14 | E17: مستلم من ناتو مشغول 18 | G17: 46182 | H17: 150 | J17: =J16+H17-I17 -> -2676 | K17: مستلم سنسال فورسا
A18: 46176 | B18: 13.92 | D18: =D17+B18-C18 -> 689.06 | E18: كادر ليرة | G18: 46182 | H18: 52 | J18: =J17+H18-I18 -> -2624 | K18: مستلم سنسال فورسا
A19: 46177 | C19: 14.89 | D19: =D18+B19-C19 -> 674.17 | E19: تصليح الى ناتو | G19: 46184 | I19: 680 | J19: =J18+H19-I19 -> -3304 | K19: ف 002812 // ريم كجوج
A20: 46177 | C20: 15.7 | D20: =D19+B20-C20 -> 658.47 | E20: تصليح الى ناتو | G20: 46184 | I20: 72 | J20: =J19+H20-I20 -> -3376 | K20: ف 002807 // جرادي
A21: 46177 | C21: 114.65 | D21: =D20+B21-C21 -> 543.82 | E21: فاتورة 002803 محمد سعيفان | G21: 46185 | I21: 684 | J21: =J20+H21-I21 -> -4060 | K21: ف 002808 // عيساوي
A22: 46177 | C22: 21.23 | D22: =D21+B22-C22 -> 522.59 | E22: فاتورة 002804 محمد سعيفان | G22: 46185 | I22: 528 | J22: =J21+H22-I22 -> -4588 | K22: ف 002810 // محمد عمار
A23: 46177 | C23: 122.22 | D23: =D22+B23-C23 -> 400.37 | E23: فاتورة 002805 محمد عمار | G23: 46185 | I23: 197 | J23: =J22+H23-I23 -> -4785 | K23: ف 002813 // جرادي
A24: 46178 | C24: 10.14 | D24: =D23+B24-C24 -> 390.23 | E24: تصليح الى ناتو | G24: 46185 | I24: 333 | J24: =J23+H24-I24 -> -5118 | K24: مبيع مشغول 18
A25: 46178 | B25: 5323.75 | D25: =D24+B25-C25 -> 5713.98 | E25: مستلم من اورا مشغول 18 | G25: 46188 | H25: 234 | J25: =J24+H25-I25 -> -4884 | K25: قفل
A26: 46181 | C26: 38.53 | D26: =D25+B26-C26 -> 5675.45 | E26: تسليم مازن بلاك | G26: 46189 | I26: 615 | J26: =J25+H26-I26 -> -5499 | K26: ف 002815 // اسيل
A27: 46181 | B27: 369.25 | D27: =D26+B27-C27 -> 6044.7 | E27: مستلم من ناتو مشغول 18 | G27: 46190 | I27: 1423 | J27: =J26+H27-I27 -> -6922 | K27: ف 002816 // عطولي
A28: 46182 | B28: 107.72 | D28: =D27+B28-C28 -> 6152.42 | E28: مستلم محابس من عيسى | G28: 46190 | I28: 26 | J28: =J27+H28-I28 -> -6948 | K28: ف 002818 // نبهان
A29: 46182 | B29: 26.9 | D29: =D28+B29-C29 -> 6179.32 | E29: مستلم محابس من عيسى | G29: 46196 | I29: 480 | J29: =J28+H29-I29 -> -7428 | K29: ف 002821 // جرادي
A30: 46182 | B30: 85.67 | D30: =D29+B30-C30 -> 6264.99 | E30: مستلم سنسال فورسا | G30: 46197 | I30: 131 | J30: =J29+H30-I30 -> -7559 | K30: ف 002820 // محمد عمار
A31: 46182 | B31: 29.23 | D31: =D30+B31-C31 -> 6294.22 | E31: مستلم سنسال فورسا | G31: 46198 | I31: 511 | J31: =J30+H31-I31 -> -8070 | K31: علي زهور
A32: 46183 | C32: 69.4 | D32: =D31+B32-C32 -> 6224.82 | E32: تصليح الى ناتو | G32: 46198 | H32: 125 | J32: =J31+H32-I32 -> -7945 | K32: فورسا
A33: 46183 | B33: 4.05 | D33: =D32+B33-C33 -> 6228.87 | E33: مستلم من ناتو مشغول 18 | G33: 46198 | I33: 20 | J33: =J32+H33-I33 -> -7965 | K33: مازن
A34: 46183 | B34: 57.32 | D34: =D33+B34-C34 -> 6286.19 | E34: مستلم من ناتو مشغول 18 | G34: 46202 | H34: 99 | J34: =J33+H34-I34 -> -7866 | K34: اسوارة تركيب
A35: 46183 | B35: 6.52 | D35: =D34+B35-C35 -> 6292.71 | E35: مستلم من ناتو مشغول 18 | G35: 46203 | I35: 110 | J35: =J34+H35-I35 -> -7976 | K35: اسوارة تركيب
A36: 46184 | B36: 212.64 | D36: =D35+B36-C36 -> 6505.35 | E36: مستلم من ناتو مشغول 18 | G36: 46204 | I36: 730 | J36: =J35+H36-I36 -> -8706 | K36: ف 002824 // محمد سعيفان
A37: 46184 | C37: 117.47 | D37: =D36+B37-C37 -> 6387.88 | E37: ف 002812 // ريم كجوج | G37: 46204 | I37: 20 | J37: =J36+H37-I37 -> -8726 | K37: تكبير بلاك هاني
A38: 46184 | C38: 13.09 | D38: =D37+B38-C38 -> 6374.79 | E38: ف 002807 // جرادي | G38: 46206 | I38: 1187 | J38: =J37+H38-I38 -> -9913 | K38: ف 002814 // جرادي محل
A39: 46184 | B39: 175.26 | D39: =D38+B39-C39 -> 6550.05 | E39: مستلم من ناتو مشغول 18 | G39: 46206 | I39: 2912 | J39: =J38+H39-I39 -> -12825 | K39: ف 002819 // طوني سعد
A40: 46185 | C40: 127.92 | D40: =D39+B40-C40 -> 6422.13 | E40: ف 002808 // عيساوي | G40: 46206 | I40: 5820 | J40: =J39+H40-I40 -> -18645 | K40: ف 002822 // سليم عطالله
A41: 46185 | C41: 92.6 | D41: =D40+B41-C41 -> 6329.53 | E41: ف 002810 // محمد عمار | G41: 46206 | I41: 317 | J41: =J40+H41-I41 -> -18962 | K41: ف 002826 // جرادي محل
...

Sheet K18
A2: K18 - 740 | D2: خارجي
A3: من تاريخ :
A4: إلى تاريخ :
A5: التاريخ | B5: دخول | C5: خروج | D5: الرصيد | E5: البيان
A6: 46164 | B6: 32.96 | D6: =B6-C6 -> 32.96
A7: 46177 | B7: 116.78 | D7: =D6+B7-C7 -> 149.74 | E7: ف 002803 محمد سعيفان
A8: 46177 | B8: 13.82 | D8: =D7+B8-C8 -> 163.56 | E8: ف 002804 محمد سعيفان
A9: 46178 | B9: 407.58 | D9: =D8+B9-C9 -> 571.14 | E9: مستلم من اورا كسر 18
A10: 46183 | C10: 1.24 | D10: =D9+B10-C10 -> 569.9 | E10: قفل
A11: 46184 | B11: 13.32 | D11: =D10+B11-C11 -> 583.22 | E11: ف 002807 // جرادي
A12: 46190 | B12: 4.85 | D12: =D11+B12-C12 -> 588.07 | E12: ف 002818 // نبهان
A13: 46190 | B13: 50.5 | D13: =D12+B13-C13 -> 638.57 | E13: تبديل جرادي
A14: 46190 | B14: 31.9 | D14: =D13+B14-C14 -> 670.47 | E14: شراء
A15: 46196 | B15: 29.17 | D15: =D14+B15-C15 -> 699.64 | E15: ف 002821 // جرادي
A16: 46197 | B16: 4 | D16: =D15+B16-C16 -> 703.64 | E16: شراء
A17: 46204 | B17: 1.17 | D17: =D16+B17-C17 -> 704.81 | E17: تكبير بلاك هاني
A18: 46206 | B18: =55.94+16.13 -> 72.07 | D18: =D17+B18-C18 -> 776.88 | E18: ف 002826 // جرادي محل
A19: 46206 | B19: 279.85 | D19: =D18+B19-C19 -> 1056.73 | E19: ف 002828 // سليم عطالله
A20: 46206 | C20: 6 | D20: =D19+B20-C20 -> 1050.73 | E20: قفل
A21: 46210 | C21: 103.18 | D21: =D20+B21-C21 -> 947.55 | E21: ف 002831 // عطولي
A22: 46210 | B22: 49.3 | D22: =D21+B22-C22 -> 996.85 | E22: ف 002832 // جرادي محل
A23: 46210 | B23: 130.62 | D23: =D22+B23-C23 -> 1127.47 | E23: ف 002833 // جرادي
A24: 46211 | B24: =206.5+3.89 -> 210.39 | D24: =D23+B24-C24 -> 1337.86 | E24: ف 002834 // سليم عطالله
A25: 46211 | C25: 1303 | D25: =D24+B25-C25 -> 34.86 | E25: صب
A26: 46220 | B26: 15.02 | D26: =D25+B26-C26 -> 49.88 | E26: مجوهرات صالح
A27: 46220 | B27: =31.63+24.56 -> 56.19 | D27: =D26+B27-C27 -> 106.07 | E27: ف 002846 // محمد سعيفان
A28: 46220 | B28: 12.56 | D28: =D27+B28-C28 -> 118.63 | E28: ف 002906 // تيما
A29: 46223 | B29: 158.6 | D29: =D28+B29-C29 -> 277.23 | E29: ف 002911 // سليم عطالله
A30: 46226 | B30: 6.76 | D30: =D29+B30-C30 -> 283.99 | E30: ف 002914 // جرادي محل
A31: 46226 | B31: 23.78 | D31: =D30+B31-C31 -> 307.77 | E31: ف 002918 // نور حسون
A32: 46231 | B32: 51.02 | D32: =D31+B32-C32 -> 358.79 | E32: ف 002926 // ابو العبد
A33: 46232 | B33: 0.78 | D33: =D32+B33-C33 -> 359.57
A34: 46233 | B34: 11.7 | D34: =D33+B34-C34 -> 371.27
A35: 46234 | B35: 25.19 | D35: =D34+B35-C35 -> 396.46 | E35: ف 002935 // سليم عطالله
A36: 46238 | B36: 29.81 | D36: =D35+B36-C36 -> 426.27 | E36: هلا محسن
B37: 326.37 | D37: =D36+B37-C37 -> 752.64 | E37: ف 002949 // علي زهور
B38: 89.03 | D38: =D37+B38-C38 -> 841.67 | E38: ف 002950 // جرادي
B39: 43.6 | D39: =D38+B39-C39 -> 885.27 | E39: ف 002851 // سليم عطالله
A40: 46245 | B40: 41.21 | D40: =D39+B40-C40 -> 926.48 | E40: ف 002852 // تيما
A41: 46245 | B41: 12.42 | D41: =D40+B41-C41 -> 938.9 | E41: ف 002859 // محمد قنديل
...

Sheet K22
A2: K22 - 905 | D2: خارجي
A3: من تاريخ :
A4: إلى تاريخ :
A5: التاريخ | B5: دخول | C5: خروج | D5: الرصيد | E5: البيان
A6: 46220 | B6: =16.39+8 -> 24.39 | D6: =B6-C6 -> 24.39 | E6: ف 002846 // محمد سعيفان
A7: 46226 | B7: 14.6 | D7: =D6+B7-C7 -> 38.99 | E7: ف 002914 // جرادي محل
A8: 46247 | C8: 38.99 | D8: =D7+B8-C8 -> 0 | E8: تعديل جردة
A9: 46261 | B9: 14.52 | D9: =D8+B9-C9 -> 14.52 | E9: ف 4454 // حسين شرف
C10: 14.52 | D10: =D9+B10-C10 -> 0
D11: =D10+B11-C11 -> 0
D12: =D11+B12-C12 -> 0
D13: =D12+B13-C13 -> 0
D14: =D13+B14-C14 -> 0
D15: =D14+B15-C15 -> 0
D16: =D15+B16-C16 -> 0
D17: =D16+B17-C17 -> 0
D18: =D17+B18-C18 -> 0
D19: =D18+B19-C19 -> 0
D20: =D19+B20-C20 -> 0
D21: =D20+B21-C21 -> 0
D22: =D21+B22-C22 -> 0
... D102: =D101+B102-C102 -> 0
A103: المجموع | B103: =SUM(B6:B102) -> 53.51 | C103: =SUM(C6:C102) -> 53.51 | D103: =B103-C103 -> 0
A104: الرصيد | B104: =B103-C103 -> 0

Sheet K21
A2: K21 - 865 | D2: خارجي
A3: من تاريخ :
A4: إلى تاريخ :
A5: التاريخ | B5: دخول | C5: خروج | D5: الرصيد | E5: البيان
A6: 46177 | B6: 3.79 | D6: =B6-C6 -> 3.79 | E6: ف 002804 محمد سعيفان
A7: 46178 | B7: 103.78 | D7: =D6+B7-C7 -> 107.57 | E7: مستلم من اورا كسر 21
A8: 46190 | B8: 59.38 | D8: =D7+B8-C8 -> 166.95 | E8: شراء
A9: 46197 | B9: 2 | D9: =D8+B9-C9 -> 168.95 | E9: شراء
A10: 46206 | B10: 6.74 | D10: =D9+B10-C10 -> 175.69 | E10: ف 002826 // جرادي محل
